nohup: ignoring input
[33mgpu id (to use): 0[0m
[33mTrain mode[0m
/root/anaconda3/envs/dp3/lib/python3.8/site-packages/hydra/_internal/defaults_list.py:251: UserWarning: In 'dp3.yaml': Defaults list is missing `_self_`. See https://hydra.cc/docs/upgrades/1.0_to_1.1/default_composition_order for more information
  warnings.warn(msg, UserWarning)
[DP3Encoder] point cloud shape: [512, 3]
[DP3Encoder] state shape: [24]
[DP3Encoder] imagination point shape: None
[PointNetEncoderXYZ] use_layernorm: True
[PointNetEncoderXYZ] use_final_norm: layernorm
[DP3Encoder] output dim: 128
[DiffusionUnetHybridPointcloudPolicy] use_pc_color: False
[DiffusionUnetHybridPointcloudPolicy] pointnet_type: pointnet
[2024-06-02 12:56:04,938][diffusion_policy_3d.model.diffusion.conditional_unet1d][INFO] - number of parameters: 2.551605e+08
----------------------------------
Class name: DP3
  Number of parameters: 255.2253M
   _dummy_variable: 0.0000M (0.00%)
   obs_encoder: 0.0648M (0.03%)
   model: 255.1605M (99.97%)
   mask_generator: 0.0000M (0.00%)
----------------------------------
Error executing job with overrides: ['task=dexterous_cheers', 'training.debug=False', 'training.seed=0', 'training.device=cuda:0', 'exp_name=dexterous_cheers-dp3-0010', 'logging.mode=online', 'checkpoint.save_ckpt=True']
Traceback (most recent call last):
  File "/root/anaconda3/envs/dp3/lib/python3.8/site-packages/hydra/_internal/instantiate/_instantiate2.py", line 92, in _call_target
    return _target_(*args, **kwargs)
  File "/root/3D-Diffusion-Policy/3D-Diffusion-Policy/diffusion_policy_3d/dataset/dexterous_dataset.py", line 25, in __init__
    self.replay_buffer = ReplayBuffer.copy_from_path(
  File "/root/3D-Diffusion-Policy/3D-Diffusion-Policy/diffusion_policy_3d/common/replay_buffer.py", line 224, in copy_from_path
    group = zarr.open(os.path.expanduser(zarr_path), 'r')
  File "/root/anaconda3/envs/dp3/lib/python3.8/site-packages/zarr/convenience.py", line 122, in open
    raise PathNotFoundError(path)
zarr.errors.PathNotFoundError: nothing found at path ''

The above exception was the direct cause of the following exception:

Traceback (most recent call last):
  File "train.py", line 506, in <module>
    main()
  File "/root/anaconda3/envs/dp3/lib/python3.8/site-packages/hydra/main.py", line 90, in decorated_main
    _run_hydra(
  File "/root/anaconda3/envs/dp3/lib/python3.8/site-packages/hydra/_internal/utils.py", line 389, in _run_hydra
    _run_app(
  File "/root/anaconda3/envs/dp3/lib/python3.8/site-packages/hydra/_internal/utils.py", line 452, in _run_app
    run_and_report(
  File "/root/anaconda3/envs/dp3/lib/python3.8/site-packages/hydra/_internal/utils.py", line 216, in run_and_report
    raise ex
  File "/root/anaconda3/envs/dp3/lib/python3.8/site-packages/hydra/_internal/utils.py", line 213, in run_and_report
    return func()
  File "/root/anaconda3/envs/dp3/lib/python3.8/site-packages/hydra/_internal/utils.py", line 453, in <lambda>
    lambda: hydra.run(
  File "/root/anaconda3/envs/dp3/lib/python3.8/site-packages/hydra/_internal/hydra.py", line 132, in run
    _ = ret.return_value
  File "/root/anaconda3/envs/dp3/lib/python3.8/site-packages/hydra/core/utils.py", line 260, in return_value
    raise self._return_value
  File "/root/anaconda3/envs/dp3/lib/python3.8/site-packages/hydra/core/utils.py", line 186, in run_job
    ret.return_value = task_function(task_cfg)
  File "train.py", line 503, in main
    workspace.run()
  File "train.py", line 101, in run
    dataset = hydra.utils.instantiate(cfg.task.dataset)
  File "/root/anaconda3/envs/dp3/lib/python3.8/site-packages/hydra/_internal/instantiate/_instantiate2.py", line 222, in instantiate
    return instantiate_node(
  File "/root/anaconda3/envs/dp3/lib/python3.8/site-packages/hydra/_internal/instantiate/_instantiate2.py", line 339, in instantiate_node
    return _call_target(_target_, partial, args, kwargs, full_key)
  File "/root/anaconda3/envs/dp3/lib/python3.8/site-packages/hydra/_internal/instantiate/_instantiate2.py", line 97, in _call_target
    raise InstantiationException(msg) from e
hydra.errors.InstantiationException: Error in call to target 'diffusion_policy_3d.dataset.dexterous_dataset.DexterousDataset':
PathNotFoundError("nothing found at path ''")
full_key: task.dataset
